[2023-02-27T15:07:36.239+0000] {taskinstance.py:1083} INFO - Dependencies all met for <TaskInstance: update-filter.gcs_sensor manual__2023-02-27T15:07:34.463473+00:00 [queued]>
[2023-02-27T15:07:36.244+0000] {taskinstance.py:1083} INFO - Dependencies all met for <TaskInstance: update-filter.gcs_sensor manual__2023-02-27T15:07:34.463473+00:00 [queued]>
[2023-02-27T15:07:36.244+0000] {taskinstance.py:1279} INFO - 
--------------------------------------------------------------------------------
[2023-02-27T15:07:36.245+0000] {taskinstance.py:1280} INFO - Starting attempt 1 of 1
[2023-02-27T15:07:36.245+0000] {taskinstance.py:1281} INFO - 
--------------------------------------------------------------------------------
[2023-02-27T15:07:36.251+0000] {taskinstance.py:1300} INFO - Executing <Task(GCSObjectExistenceSensor): gcs_sensor> on 2023-02-27 15:07:34.463473+00:00
[2023-02-27T15:07:36.256+0000] {standard_task_runner.py:55} INFO - Started process 210 to run task
[2023-02-27T15:07:36.259+0000] {standard_task_runner.py:82} INFO - Running: ['***', 'tasks', 'run', 'update-filter', 'gcs_sensor', 'manual__2023-02-27T15:07:34.463473+00:00', '--job-id', '25', '--raw', '--subdir', 'DAGS_FOLDER/update-filter.py', '--cfg-path', '/tmp/tmp6t0_cy_x']
[2023-02-27T15:07:36.261+0000] {standard_task_runner.py:83} INFO - Job 25: Subtask gcs_sensor
[2023-02-27T15:07:36.303+0000] {task_command.py:388} INFO - Running <TaskInstance: update-filter.gcs_sensor manual__2023-02-27T15:07:34.463473+00:00 [running]> on host d766c014b21e
[2023-02-27T15:07:36.343+0000] {taskinstance.py:1509} INFO - Exporting the following env vars:
AIRFLOW_CTX_DAG_OWNER=***
AIRFLOW_CTX_DAG_ID=update-filter
AIRFLOW_CTX_TASK_ID=gcs_sensor
AIRFLOW_CTX_EXECUTION_DATE=2023-02-27T15:07:34.463473+00:00
AIRFLOW_CTX_TRY_NUMBER=1
AIRFLOW_CTX_DAG_RUN_ID=manual__2023-02-27T15:07:34.463473+00:00
[2023-02-27T15:07:36.345+0000] {gcs.py:89} INFO - Sensor checks existence of : ***-gcs-bq, update.csv
[2023-02-27T15:07:36.359+0000] {taskinstance.py:1768} ERROR - Task failed with exception
Traceback (most recent call last):
  File "/home/airflow/.local/lib/python3.7/site-packages/airflow/sensors/base.py", line 199, in execute
    poke_return = self.poke(context)
  File "/home/airflow/.local/lib/python3.7/site-packages/airflow/providers/google/cloud/sensors/gcs.py", line 93, in poke
    impersonation_chain=self.impersonation_chain,
  File "/home/airflow/.local/lib/python3.7/site-packages/airflow/providers/google/cloud/hooks/gcs.py", line 150, in __init__
    impersonation_chain=impersonation_chain,
  File "/home/airflow/.local/lib/python3.7/site-packages/airflow/providers/google/common/hooks/base_google.py", line 231, in __init__
    self.extras: dict = self.get_connection(self.gcp_conn_id).extra_dejson
  File "/home/airflow/.local/lib/python3.7/site-packages/airflow/hooks/base.py", line 72, in get_connection
    conn = Connection.get_connection_from_secrets(conn_id)
  File "/home/airflow/.local/lib/python3.7/site-packages/airflow/models/connection.py", line 435, in get_connection_from_secrets
    raise AirflowNotFoundException(f"The conn_id `{conn_id}` isn't defined")
airflow.exceptions.AirflowNotFoundException: The conn_id `google_cloud_default` isn't defined
[2023-02-27T15:07:36.362+0000] {taskinstance.py:1323} INFO - Marking task as FAILED. dag_id=update-filter, task_id=gcs_sensor, execution_date=20230227T150734, start_date=20230227T150736, end_date=20230227T150736
[2023-02-27T15:07:36.369+0000] {standard_task_runner.py:105} ERROR - Failed to execute job 25 for task gcs_sensor (The conn_id `google_cloud_default` isn't defined; 210)
[2023-02-27T15:07:36.391+0000] {local_task_job.py:208} INFO - Task exited with return code 1
[2023-02-27T15:07:36.410+0000] {taskinstance.py:2578} INFO - 0 downstream tasks scheduled from follow-on schedule check
