[2023-02-24T22:45:46.592+0000] {taskinstance.py:1083} INFO - Dependencies all met for <TaskInstance: update-filter.gcs_sensor manual__2023-02-24T22:45:45.616602+00:00 [queued]>
[2023-02-24T22:45:46.596+0000] {taskinstance.py:1083} INFO - Dependencies all met for <TaskInstance: update-filter.gcs_sensor manual__2023-02-24T22:45:45.616602+00:00 [queued]>
[2023-02-24T22:45:46.597+0000] {taskinstance.py:1279} INFO - 
--------------------------------------------------------------------------------
[2023-02-24T22:45:46.597+0000] {taskinstance.py:1280} INFO - Starting attempt 1 of 1
[2023-02-24T22:45:46.598+0000] {taskinstance.py:1281} INFO - 
--------------------------------------------------------------------------------
[2023-02-24T22:45:46.605+0000] {taskinstance.py:1300} INFO - Executing <Task(GCSObjectExistenceSensor): gcs_sensor> on 2023-02-24 22:45:45.616602+00:00
[2023-02-24T22:45:46.610+0000] {standard_task_runner.py:55} INFO - Started process 299 to run task
[2023-02-24T22:45:46.612+0000] {standard_task_runner.py:82} INFO - Running: ['***', 'tasks', 'run', 'update-filter', 'gcs_sensor', 'manual__2023-02-24T22:45:45.616602+00:00', '--job-id', '7', '--raw', '--subdir', 'DAGS_FOLDER/update-filter.py', '--cfg-path', '/tmp/tmpeky2u1q7']
[2023-02-24T22:45:46.613+0000] {standard_task_runner.py:83} INFO - Job 7: Subtask gcs_sensor
[2023-02-24T22:45:46.660+0000] {task_command.py:388} INFO - Running <TaskInstance: update-filter.gcs_sensor manual__2023-02-24T22:45:45.616602+00:00 [running]> on host d766c014b21e
[2023-02-24T22:45:46.704+0000] {taskinstance.py:1509} INFO - Exporting the following env vars:
AIRFLOW_CTX_DAG_OWNER=***
AIRFLOW_CTX_DAG_ID=update-filter
AIRFLOW_CTX_TASK_ID=gcs_sensor
AIRFLOW_CTX_EXECUTION_DATE=2023-02-24T22:45:45.616602+00:00
AIRFLOW_CTX_TRY_NUMBER=1
AIRFLOW_CTX_DAG_RUN_ID=manual__2023-02-24T22:45:45.616602+00:00
[2023-02-24T22:45:46.706+0000] {gcs.py:89} INFO - Sensor checks existence of : ***-gcs-bq, ***-gcs-bq/update.csv
[2023-02-24T22:45:46.721+0000] {taskinstance.py:1768} ERROR - Task failed with exception
Traceback (most recent call last):
  File "/home/airflow/.local/lib/python3.7/site-packages/airflow/sensors/base.py", line 199, in execute
    poke_return = self.poke(context)
  File "/home/airflow/.local/lib/python3.7/site-packages/airflow/providers/google/cloud/sensors/gcs.py", line 93, in poke
    impersonation_chain=self.impersonation_chain,
  File "/home/airflow/.local/lib/python3.7/site-packages/airflow/providers/google/cloud/hooks/gcs.py", line 150, in __init__
    impersonation_chain=impersonation_chain,
  File "/home/airflow/.local/lib/python3.7/site-packages/airflow/providers/google/common/hooks/base_google.py", line 231, in __init__
    self.extras: dict = self.get_connection(self.gcp_conn_id).extra_dejson
  File "/home/airflow/.local/lib/python3.7/site-packages/airflow/hooks/base.py", line 72, in get_connection
    conn = Connection.get_connection_from_secrets(conn_id)
  File "/home/airflow/.local/lib/python3.7/site-packages/airflow/models/connection.py", line 435, in get_connection_from_secrets
    raise AirflowNotFoundException(f"The conn_id `{conn_id}` isn't defined")
airflow.exceptions.AirflowNotFoundException: The conn_id `***-gcs-bq` isn't defined
[2023-02-24T22:45:46.724+0000] {taskinstance.py:1323} INFO - Marking task as FAILED. dag_id=update-filter, task_id=gcs_sensor, execution_date=20230224T224545, start_date=20230224T224546, end_date=20230224T224546
[2023-02-24T22:45:46.731+0000] {standard_task_runner.py:105} ERROR - Failed to execute job 7 for task gcs_sensor (The conn_id `***-gcs-bq` isn't defined; 299)
[2023-02-24T22:45:46.745+0000] {local_task_job.py:208} INFO - Task exited with return code 1
[2023-02-24T22:45:46.764+0000] {taskinstance.py:2578} INFO - 0 downstream tasks scheduled from follow-on schedule check
