[2023-02-27T19:13:05.798+0000] {taskinstance.py:1083} INFO - Dependencies all met for <TaskInstance: update-filter.filter_insert manual__2023-02-27T19:12:55.060715+00:00 [queued]>
[2023-02-27T19:13:05.802+0000] {taskinstance.py:1083} INFO - Dependencies all met for <TaskInstance: update-filter.filter_insert manual__2023-02-27T19:12:55.060715+00:00 [queued]>
[2023-02-27T19:13:05.802+0000] {taskinstance.py:1279} INFO - 
--------------------------------------------------------------------------------
[2023-02-27T19:13:05.803+0000] {taskinstance.py:1280} INFO - Starting attempt 1 of 1
[2023-02-27T19:13:05.803+0000] {taskinstance.py:1281} INFO - 
--------------------------------------------------------------------------------
[2023-02-27T19:13:05.810+0000] {taskinstance.py:1300} INFO - Executing <Task(BigQueryInsertJobOperator): filter_insert> on 2023-02-27 19:12:55.060715+00:00
[2023-02-27T19:13:05.815+0000] {standard_task_runner.py:55} INFO - Started process 1134 to run task
[2023-02-27T19:13:05.818+0000] {standard_task_runner.py:82} INFO - Running: ['***', 'tasks', 'run', 'update-filter', 'filter_insert', 'manual__2023-02-27T19:12:55.060715+00:00', '--job-id', '51', '--raw', '--subdir', 'DAGS_FOLDER/update-filter.py', '--cfg-path', '/tmp/tmpw9ll06d6']
[2023-02-27T19:13:05.819+0000] {standard_task_runner.py:83} INFO - Job 51: Subtask filter_insert
[2023-02-27T19:13:05.860+0000] {task_command.py:388} INFO - Running <TaskInstance: update-filter.filter_insert manual__2023-02-27T19:12:55.060715+00:00 [running]> on host d766c014b21e
[2023-02-27T19:13:05.898+0000] {taskinstance.py:1509} INFO - Exporting the following env vars:
AIRFLOW_CTX_DAG_OWNER=***
AIRFLOW_CTX_DAG_ID=update-filter
AIRFLOW_CTX_TASK_ID=filter_insert
AIRFLOW_CTX_EXECUTION_DATE=2023-02-27T19:12:55.060715+00:00
AIRFLOW_CTX_TRY_NUMBER=1
AIRFLOW_CTX_DAG_RUN_ID=manual__2023-02-27T19:12:55.060715+00:00
[2023-02-27T19:13:05.912+0000] {taskinstance.py:1768} ERROR - Task failed with exception
Traceback (most recent call last):
  File "/home/airflow/.local/lib/python3.7/site-packages/airflow/providers/google/cloud/operators/bigquery.py", line 2621, in execute
    impersonation_chain=self.impersonation_chain,
  File "/home/airflow/.local/lib/python3.7/site-packages/airflow/providers/google/cloud/hooks/bigquery.py", line 103, in __init__
    impersonation_chain=impersonation_chain,
  File "/home/airflow/.local/lib/python3.7/site-packages/airflow/providers/google/common/hooks/base_google.py", line 231, in __init__
    self.extras: dict = self.get_connection(self.gcp_conn_id).extra_dejson
  File "/home/airflow/.local/lib/python3.7/site-packages/airflow/hooks/base.py", line 72, in get_connection
    conn = Connection.get_connection_from_secrets(conn_id)
  File "/home/airflow/.local/lib/python3.7/site-packages/airflow/models/connection.py", line 435, in get_connection_from_secrets
    raise AirflowNotFoundException(f"The conn_id `{conn_id}` isn't defined")
airflow.exceptions.AirflowNotFoundException: The conn_id `google_cloud_default` isn't defined
[2023-02-27T19:13:05.914+0000] {taskinstance.py:1323} INFO - Marking task as FAILED. dag_id=update-filter, task_id=filter_insert, execution_date=20230227T191255, start_date=20230227T191305, end_date=20230227T191305
[2023-02-27T19:13:05.920+0000] {standard_task_runner.py:105} ERROR - Failed to execute job 51 for task filter_insert (The conn_id `google_cloud_default` isn't defined; 1134)
[2023-02-27T19:13:05.950+0000] {local_task_job.py:208} INFO - Task exited with return code 1
[2023-02-27T19:13:05.970+0000] {taskinstance.py:2578} INFO - 0 downstream tasks scheduled from follow-on schedule check
